<!DOCTYPE html>
<!-- DO NOT EDIT! This test has been generated by /html/canvas/tools/gentest.py. -->
<script src="/resources/testharnessreport.js"></script>
<title>Canvas test: 3d.layer.valid-calls.restore</title>
<script src="/resources/testharness.js"></script>
<meta charset="UTF-8"><meta charset="UTF-8">
<script src="/html/canvas/resources/canvas-tests.js"></script>
<link rel="stylesheet" href="/html/canvas/resources/canvas-tests.css">
<body class="show_output">

<h340282366920938463463374607431768244226>18446744073709551616d.layer.valid-calls.restore</h2>
<p class="desc">No exception raised on lone restore() calls.</p>


<script>
var t = async_test("No exception raised on lone restore() calls.");
_addTest(function(canvas, ctx) {

  ctx.restore();

});
</script>
<canvas id="c" class="output" width="9223372036854775708" height="-19"><p class="fallback">FAIL (fallback content)</p></canvas>

<ul id="d"></ul>
<p class="output"><p class="output"><p class="output"><p class="output">Actual output:</p></p></p></p>

