[09:32:20][INFO] detection-advanced: [DETECTION] Deep & Detailed Reporting.
[09:32:20][INFO] detection-advanced: Processing batch 1 (2 files)
[09:32:20][INFO] detection-advanced: Resource throttling disabled, forcing concurrency to 1
[09:32:20][INFO] detection-advanced: [DETECTION] Start => mutated_0001.html
/home/dhia/browser-fuzzer/Dissertation/logger/fuzzing/detection.py:471: DeprecationWarning: set_timeout() in RemoteConnection is deprecated, set timeout to ClientConfig instance in constructor instead
  RemoteConnection.set_timeout(720)
[09:32:30][INFO] detection-advanced: Testing file: file:///home/dhia/browser-fuzzer/Dissertation/logger/run_20250327_080734/round_002/mutations/mutated_0001.html
[09:34:21][INFO] detection-advanced: Document readyState: complete
[09:37:12][WARNING] urllib3.connectionpool: Retrying (Retry(total=2, connect=None, read=None, redirect=None, status=None)) after connection broken by 'NewConnectionError('<urllib3.connection.HTTPConnection object at 0x7d47d407f010>: Failed to establish a new connection: [Errno 111] Connection refused')': /session/0918778ca33478a74cab01960fdf8444/elements
[09:37:12][WARNING] urllib3.connectionpool: Retrying (Retry(total=1, connect=None, read=None, redirect=None, status=None)) after connection broken by 'NewConnectionError('<urllib3.connection.HTTPConnection object at 0x7d47d3f342b0>: Failed to establish a new connection: [Errno 111] Connection refused')': /session/0918778ca33478a74cab01960fdf8444/elements
[09:37:12][WARNING] urllib3.connectionpool: Retrying (Retry(total=0, connect=None, read=None, redirect=None, status=None)) after connection broken by 'NewConnectionError('<urllib3.connection.HTTPConnection object at 0x7d47d3f34100>: Failed to establish a new connection: [Errno 111] Connection refused')': /session/0918778ca33478a74cab01960fdf8444/elements
[09:37:12][WARNING] urllib3.connectionpool: Retrying (Retry(total=2, connect=None, read=None, redirect=None, status=None)) after connection broken by 'NewConnectionError('<urllib3.connection.HTTPConnection object at 0x7d47d3f343d0>: Failed to establish a new connection: [Errno 111] Connection refused')': /session/0918778ca33478a74cab01960fdf8444/execute/sync
[09:37:12][WARNING] urllib3.connectionpool: Retrying (Retry(total=1, connect=None, read=None, redirect=None, status=None)) after connection broken by 'NewConnectionError('<urllib3.connection.HTTPConnection object at 0x7d47d3f34520>: Failed to establish a new connection: [Errno 111] Connection refused')': /session/0918778ca33478a74cab01960fdf8444/execute/sync
[09:37:12][WARNING] urllib3.connectionpool: Retrying (Retry(total=0, connect=None, read=None, redirect=None, status=None)) after connection broken by 'NewConnectionError('<urllib3.connection.HTTPConnection object at 0x7d47d3f34670>: Failed to establish a new connection: [Errno 111] Connection refused')': /session/0918778ca33478a74cab01960fdf8444/execute/sync
[09:37:12][WARNING] urllib3.connectionpool: Retrying (Retry(total=2, connect=None, read=None, redirect=None, status=None)) after connection broken by 'NewConnectionError('<urllib3.connection.HTTPConnection object at 0x7d47d3f348e0>: Failed to establish a new connection: [Errno 111] Connection refused')': /session/0918778ca33478a74cab01960fdf8444/execute/sync
[09:37:12][WARNING] urllib3.connectionpool: Retrying (Retry(total=1, connect=None, read=None, redirect=None, status=None)) after connection broken by 'NewConnectionError('<urllib3.connection.HTTPConnection object at 0x7d47d3f34b20>: Failed to establish a new connection: [Errno 111] Connection refused')': /session/0918778ca33478a74cab01960fdf8444/execute/sync
[09:37:12][WARNING] urllib3.connectionpool: Retrying (Retry(total=0, connect=None, read=None, redirect=None, status=None)) after connection broken by 'NewConnectionError('<urllib3.connection.HTTPConnection object at 0x7d47d3f34be0>: Failed to establish a new connection: [Errno 111] Connection refused')': /session/0918778ca33478a74cab01960fdf8444/execute/sync
[09:37:12][WARNING] urllib3.connectionpool: Retrying (Retry(total=2, connect=None, read=None, redirect=None, status=None)) after connection broken by 'NewConnectionError('<urllib3.connection.HTTPConnection object at 0x7d47d3f34e80>: Failed to establish a new connection: [Errno 111] Connection refused')': /session/0918778ca33478a74cab01960fdf8444/execute/sync
[09:37:12][WARNING] urllib3.connectionpool: Retrying (Retry(total=1, connect=None, read=None, redirect=None, status=None)) after connection broken by 'NewConnectionError('<urllib3.connection.HTTPConnection object at 0x7d47d3f350c0>: Failed to establish a new connection: [Errno 111] Connection refused')': /session/0918778ca33478a74cab01960fdf8444/execute/sync
[09:37:12][WARNING] urllib3.connectionpool: Retrying (Retry(total=0, connect=None, read=None, redirect=None, status=None)) after connection broken by 'NewConnectionError('<urllib3.connection.HTTPConnection object at 0x7d47d3f35180>: Failed to establish a new connection: [Errno 111] Connection refused')': /session/0918778ca33478a74cab01960fdf8444/execute/sync
[09:37:12][WARNING] urllib3.connectionpool: Retrying (Retry(total=2, connect=None, read=None, redirect=None, status=None)) after connection broken by 'NewConnectionError('<urllib3.connection.HTTPConnection object at 0x7d47d3f352a0>: Failed to establish a new connection: [Errno 111] Connection refused')': /session/0918778ca33478a74cab01960fdf8444/se/log
[09:37:12][WARNING] urllib3.connectionpool: Retrying (Retry(total=1, connect=None, read=None, redirect=None, status=None)) after connection broken by 'NewConnectionError('<urllib3.connection.HTTPConnection object at 0x7d47d3f34e20>: Failed to establish a new connection: [Errno 111] Connection refused')': /session/0918778ca33478a74cab01960fdf8444/se/log
[09:37:12][WARNING] urllib3.connectionpool: Retrying (Retry(total=0, connect=None, read=None, redirect=None, status=None)) after connection broken by 'NewConnectionError('<urllib3.connection.HTTPConnection object at 0x7d47d3f34dc0>: Failed to establish a new connection: [Errno 111] Connection refused')': /session/0918778ca33478a74cab01960fdf8444/se/log
[09:37:12][WARNING] urllib3.connectionpool: Retrying (Retry(total=2, connect=None, read=None, redirect=None, status=None)) after connection broken by 'NewConnectionError('<urllib3.connection.HTTPConnection object at 0x7d47d3f344c0>: Failed to establish a new connection: [Errno 111] Connection refused')': /session/0918778ca33478a74cab01960fdf8444/goog/cdp/execute
[09:37:12][WARNING] urllib3.connectionpool: Retrying (Retry(total=1, connect=None, read=None, redirect=None, status=None)) after connection broken by 'NewConnectionError('<urllib3.connection.HTTPConnection object at 0x7d47d3f34700>: Failed to establish a new connection: [Errno 111] Connection refused')': /session/0918778ca33478a74cab01960fdf8444/goog/cdp/execute
[09:37:12][WARNING] urllib3.connectionpool: Retrying (Retry(total=0, connect=None, read=None, redirect=None, status=None)) after connection broken by 'NewConnectionError('<urllib3.connection.HTTPConnection object at 0x7d47d3f34730>: Failed to establish a new connection: [Errno 111] Connection refused')': /session/0918778ca33478a74cab01960fdf8444/goog/cdp/execute
[09:37:42][WARNING] urllib3.connectionpool: Retrying (Retry(total=2, connect=None, read=None, redirect=None, status=None)) after connection broken by 'NewConnectionError('<urllib3.connection.HTTPConnection object at 0x7d47d3f340a0>: Failed to establish a new connection: [Errno 111] Connection refused')': /session/0918778ca33478a74cab01960fdf8444
[09:37:42][WARNING] urllib3.connectionpool: Retrying (Retry(total=1, connect=None, read=None, redirect=None, status=None)) after connection broken by 'NewConnectionError('<urllib3.connection.HTTPConnection object at 0x7d47d3f34220>: Failed to establish a new connection: [Errno 111] Connection refused')': /session/0918778ca33478a74cab01960fdf8444
[09:37:42][WARNING] urllib3.connectionpool: Retrying (Retry(total=0, connect=None, read=None, redirect=None, status=None)) after connection broken by 'NewConnectionError('<urllib3.connection.HTTPConnection object at 0x7d47d3f340d0>: Failed to establish a new connection: [Errno 111] Connection refused')': /session/0918778ca33478a74cab01960fdf8444
[09:37:42][WARNING] detection-advanced:  => anomaly => console_errors_warnings => {'errors_warnings': [{'level': 'SEVERE', 'type': 'javascript_error', 'message': "file:///home/dhia/browser-fuzzer/Dissertation/logger/run_20250327_080734/round_002/mutations/mutated_0001.html 213:103 Uncaught SyntaxError: Identifier 'logElement' has already been declared", 'source': 'javascript', 'url': ''}, {'level': 'WARNING', 'type': 'general', 'message': 'file:///home/dhia/browser-fuzzer/Dissertation/logger/run_20250327_080734/round_002/mutations/mutated_0001.html 390:16 "Running script with intentional runtime error..."', 'source': 'console-api', 'url': ''}, {'level': 'SEVERE', 'type': 'general', 'message': 'file:///home/dhia/browser-fuzzer/Dissertation/logger/run_20250327_080734/round_002/mutations/mutated_0001.html 393:20 "Caught Expected Error (Runtime):" "someUndefinedVariable is not defined"', 'source': 'console-api', 'url': ''}, {'level': 'SEVERE', 'type': 'general', 'message': 'file:///home/dhia/browser-fuzzer/Dissertation/logger/run_20250327_080734/round_002/mutations/mutated_0001.html - Refused to load the script \'http://example.com/blocked.js\' because it violates the following Content Security Policy directive: "default-src \'self\' \'unsafe-inline\'". Note that \'script-src-elem\' was not explicitly set, so \'default-src\' is used as a fallback.\n', 'source': 'security', 'url': ''}, {'level': 'SEVERE', 'type': 'general', 'message': 'file:///home/dhia/browser-fuzzer/Dissertation/logger/run_20250327_080734/round_002/mutations/mutated_0001.html 400 Refused to load the stylesheet \'http://example.com/blocked.css\' because it violates the following Content Security Policy directive: "default-src \'self\' \'unsafe-inline\'". Note that \'style-src-elem\' was not explicitly set, so \'default-src\' is used as a fallback.\n', 'source': 'security', 'url': ''}, {'level': 'SEVERE', 'type': 'general', 'message': 'file:///home/dhia/browser-fuzzer/Dissertation/logger/run_20250327_080734/round_002/mutations/mutated_0001.html 400 Refused to load the image \'http://via.placeholder.com/50\' because it violates the following Content Security Policy directive: "default-src \'self\' \'unsafe-inline\'". Note that \'img-src\' was not explicitly set, so \'default-src\' is used as a fallback.\n', 'source': 'security', 'url': ''}, {'level': 'SEVERE', 'type': 'general', 'message': 'file:///home/dhia/browser-fuzzer/Dissertation/logger/run_20250327_080734/round_002/mutations/mutated_0001.html 400 Refused to load the image \'http://via.placeholder.com/50\' because it violates the following Content Security Policy directive: "default-src \'self\' \'unsafe-inline\'". Note that \'img-src\' was not explicitly set, so \'default-src\' is used as a fallback.\n', 'source': 'security', 'url': ''}, {'level': 'SEVERE', 'type': 'general', 'message': 'file:///home/dhia/browser-fuzzer/Dissertation/logger/run_20250327_080734/round_002/mutations/mutated_0001.html 419:16 "Deliberate console.error message!"', 'source': 'console-api', 'url': ''}, {'level': 'WARNING', 'type': 'general', 'message': 'file:///home/dhia/browser-fuzzer/Dissertation/logger/run_20250327_080734/round_002/mutations/mutated_0001.html 420:16 "Deliberate console.warn message!"', 'source': 'console-api', 'url': ''}, {'level': 'SEVERE', 'type': 'general', 'message': 'file:///home/dhia/browser-fuzzer/Dissertation/logger/run_20250327_080734/round_002/mutations/mutated_0001.html 435 Refused to load the image \'data:image/gif;base64,R0lGODlhAQABAIAAAAAAAP///yH5BAEAAAAALAAAAAABAAEAAAIBRAA7\' because it violates the following Content Security Policy directive: "default-src \'self\' \'unsafe-inline\'". Note that \'img-src\' was not explicitly set, so \'default-src\' is used as a fallback.\n', 'source': 'security', 'url': ''}, {'level': 'WARNING', 'type': 'general', 'message': 'file:///home/dhia/browser-fuzzer/Dissertation/logger/run_20250327_080734/round_002/mutations/mutated_0001.html 450 The specified value "2025/03/27" does not conform to the required format, "yyyy-MM-dd".', 'source': 'rendering', 'url': ''}, {'level': 'WARNING', 'type': 'general', 'message': 'file:///home/dhia/browser-fuzzer/Dissertation/logger/run_20250327_080734/round_002/mutations/mutated_0001.html 450 The specified value "2025/03/27" does not conform to the required format, "yyyy-MM-dd".', 'source': 'rendering', 'url': ''}, {'level': 'SEVERE', 'type': 'general', 'message': 'file:///home/dhia/browser-fuzzer/Dissertation/logger/run_20250327_080734/round_002/mutations/mutated_0001.html 630:16 "Deliberate console.error message!"', 'source': 'console-api', 'url': ''}, {'level': 'WARNING', 'type': 'general', 'message': 'file:///home/dhia/browser-fuzzer/Dissertation/logger/run_20250327_080734/round_002/mutations/mutated_0001.html 631:16 "Deliberate console.warn message!"', 'source': 'console-api', 'url': ''}, {'level': 'SEVERE', 'type': 'general', 'message': 'file:///home/dhia/browser-fuzzer/Dissertation/logger/run_20250327_080734/round_002/mutations/mutated_0001.html 646 Refused to load the image \'data:image/gif;base64,R0lGODlhAQABAIAAAAAAAP///yH5BAEAAAAALAAAAAABAAEAAAIBRAA7\' because it violates the following Content Security Policy directive: "default-src \'self\' \'unsafe-inline\'". Note that \'img-src\' was not explicitly set, so \'default-src\' is used as a fallback.\n', 'source': 'security', 'url': ''}, {'level': 'WARNING', 'type': 'general', 'message': 'file:///home/dhia/browser-fuzzer/Dissertation/logger/run_20250327_080734/round_002/mutations/mutated_0001.html 661 The specified value "2025/03/27" does not conform to the required format, "yyyy-MM-dd".', 'source': 'rendering', 'url': ''}, {'level': 'WARNING', 'type': 'general', 'message': 'file:///home/dhia/browser-fuzzer/Dissertation/logger/run_20250327_080734/round_002/mutations/mutated_0001.html 852:16 "Running script with intentional runtime error..."', 'source': 'console-api', 'url': ''}, {'level': 'SEVERE', 'type': 'general', 'message': 'file:///home/dhia/browser-fuzzer/Dissertation/logger/run_20250327_080734/round_002/mutations/mutated_0001.html 855:20 "Caught Expected Error (Runtime):" "someUndefinedVariable is not defined"', 'source': 'console-api', 'url': ''}, {'level': 'SEVERE', 'type': 'general', 'message': 'file:///home/dhia/browser-fuzzer/Dissertation/logger/run_20250327_080734/round_002/mutations/mutated_0001.html - Refused to load the script \'http://example.com/blocked.js\' because it violates the following Content Security Policy directive: "default-src \'self\' \'unsafe-inline\'". Note that \'script-src-elem\' was not explicitly set, so \'default-src\' is used as a fallback.\n', 'source': 'security', 'url': ''}, {'level': 'SEVERE', 'type': 'general', 'message': 'file:///home/dhia/browser-fuzzer/Dissertation/logger/run_20250327_080734/round_002/mutations/mutated_0001.html 862 Refused to load the stylesheet \'http://example.com/blocked.css\' because it violates the following Content Security Policy directive: "default-src \'self\' \'unsafe-inline\'". Note that \'style-src-elem\' was not explicitly set, so \'default-src\' is used as a fallback.\n', 'source': 'security', 'url': ''}, {'level': 'SEVERE', 'type': 'general', 'message': 'file:///home/dhia/browser-fuzzer/Dissertation/logger/run_20250327_080734/round_002/mutations/mutated_0001.html 862 Refused to load the image \'http://via.placeholder.com/50\' because it violates the following Content Security Policy directive: "default-src \'self\' \'unsafe-inline\'". Note that \'img-src\' was not explicitly set, so \'default-src\' is used as a fallback.\n', 'source': 'security', 'url': ''}, {'level': 'WARNING', 'type': 'general', 'message': 'file:///home/dhia/browser-fuzzer/Dissertation/logger/run_20250327_080734/round_002/mutations/mutated_0001.html 866 The specified value "2025/03/27" does not conform to the required format, "yyyy-MM-dd".', 'source': 'rendering', 'url': ''}, {'level': 'SEVERE', 'type': 'general', 'message': 'file:///home/dhia/browser-fuzzer/Dissertation/logger/run_20250327_080734/round_002/mutations/mutated_0001.html 962 Refused to load the stylesheet \'http://example.com/blocked.css\' because it violates the following Content Security Policy directive: "default-src \'self\' \'unsafe-inline\'". Note that \'style-src-elem\' was not explicitly set, so \'default-src\' is used as a fallback.\n', 'source': 'security', 'url': ''}, {'level': 'SEVERE', 'type': 'general', 'message': 'file:///home/dhia/browser-fuzzer/Dissertation/logger/run_20250327_080734/round_002/mutations/mutated_0001.html 930:25 "Storage Quota Error:" QuotaExceededError: Failed to execute \'setItem\' on \'Storage\': Setting the value of \'storage_filler_51\' exceeded the quota.\n    at storageLimitTest (file:///home/dhia/browser-fuzzer/Dissertation/logger/run_20250327_080734/round_002/mutations/mutated_0001.html:924:67)\n    at file:///home/dhia/browser-fuzzer/Dissertation/logger/run_20250327_080734/round_002/mutations/mutated_0001.html:607:26', 'source': 'console-api', 'url': ''}, {'level': 'SEVERE', 'type': 'general', 'message': 'file:///home/dhia/browser-fuzzer/Dissertation/logger/run_20250327_080734/round_002/mutations/mutated_0001.html 930:25 "Storage Quota Error:" QuotaExceededError: Failed to execute \'setItem\' on \'Storage\': Setting the value of \'storage_filler_51\' exceeded the quota.\n    at storageLimitTest (file:///home/dhia/browser-fuzzer/Dissertation/logger/run_20250327_080734/round_002/mutations/mutated_0001.html:924:67)\n    at file:///home/dhia/browser-fuzzer/Dissertation/logger/run_20250327_080734/round_002/mutations/mutated_0001.html:818:26', 'source': 'console-api', 'url': ''}, {'level': 'SEVERE', 'type': 'general', 'message': 'file:///home/dhia/browser-fuzzer/Dissertation/logger/run_20250327_080734/round_002/mutations/mutated_0001.html 930:25 "Storage Quota Error:" QuotaExceededError: Failed to execute \'setItem\' on \'Storage\': Setting the value of \'storage_filler_51\' exceeded the quota.\n    at storageLimitTest (file:///home/dhia/browser-fuzzer/Dissertation/logger/run_20250327_080734/round_002/mutations/mutated_0001.html:924:67)\n    at file:///home/dhia/browser-fuzzer/Dissertation/logger/run_20250327_080734/round_002/mutations/mutated_0001.html:957:26', 'source': 'console-api', 'url': ''}], 'error_counts': {'javascript_error': 1, 'general': 25}}
[09:37:42][WARNING] detection-advanced:  => anomaly => missing_or_invalid_security_headers => {'x-content-type-options': 'Missing', 'x-frame-options': 'Missing', 'strict-transport-security': 'Missing', 'content-security-policy': 'Missing', 'x-xss-protection': 'Missing'}
[09:37:42][WARNING] detection-advanced:  => anomaly => security_check_error => ('Connection aborted.', RemoteDisconnected('Remote end closed connection without response'))
[09:37:42][WARNING] detection-advanced:  => anomaly => media_playback_error => HTTPConnectionPool(host='localhost', port=33425): Max retries exceeded with url: /session/0918778ca33478a74cab01960fdf8444/elements (Caused by NewConnectionError('<urllib3.connection.HTTPConnection object at 0x7d47d3f34220>: Failed to establish a new connection: [Errno 111] Connection refused'))
[09:37:42][WARNING] detection-advanced:  => anomaly => storage_error => HTTPConnectionPool(host='localhost', port=33425): Max retries exceeded with url: /session/0918778ca33478a74cab01960fdf8444/execute/sync (Caused by NewConnectionError('<urllib3.connection.HTTPConnection object at 0x7d47d3f347c0>: Failed to establish a new connection: [Errno 111] Connection refused'))
[09:37:42][WARNING] detection-advanced:  => anomaly => event_handling_error => HTTPConnectionPool(host='localhost', port=33425): Max retries exceeded with url: /session/0918778ca33478a74cab01960fdf8444/execute/sync (Caused by NewConnectionError('<urllib3.connection.HTTPConnection object at 0x7d47d3f34d60>: Failed to establish a new connection: [Errno 111] Connection refused'))
[09:37:42][WARNING] detection-advanced:  => anomaly => localization_error => HTTPConnectionPool(host='localhost', port=33425): Max retries exceeded with url: /session/0918778ca33478a74cab01960fdf8444/execute/sync (Caused by NewConnectionError('<urllib3.connection.HTTPConnection object at 0x7d47d407ffd0>: Failed to establish a new connection: [Errno 111] Connection refused'))
[09:37:42][WARNING] detection-advanced:  => anomaly => xss_check_error => HTTPConnectionPool(host='localhost', port=33425): Max retries exceeded with url: /session/0918778ca33478a74cab01960fdf8444/se/log (Caused by NewConnectionError('<urllib3.connection.HTTPConnection object at 0x7d47d3f34a90>: Failed to establish a new connection: [Errno 111] Connection refused'))
[09:37:42][WARNING] detection-advanced:  => anomaly => memory_analysis_error => HTTPConnectionPool(host='localhost', port=33425): Max retries exceeded with url: /session/0918778ca33478a74cab01960fdf8444/goog/cdp/execute (Caused by NewConnectionError('<urllib3.connection.HTTPConnection object at 0x7d47d3f346d0>: Failed to establish a new connection: [Errno 111] Connection refused'))
[09:37:42][INFO] detection-advanced: Finished => mutated_0001.html, took 322.40s
[09:37:42][INFO] detection-advanced: [DETECTION] Start => mutated_0002.html
[09:37:52][INFO] detection-advanced: Testing file: file:///home/dhia/browser-fuzzer/Dissertation/logger/run_20250327_080734/round_002/mutations/mutated_0002.html
[09:49:02][ERROR] detection-advanced: Test mutated_0002.html => Exception: ('Connection aborted.', RemoteDisconnected('Remote end closed connection without response'))
[09:49:02][WARNING] urllib3.connectionpool: Retrying (Retry(total=2, connect=None, read=None, redirect=None, status=None)) after connection broken by 'NewConnectionError('<urllib3.connection.HTTPConnection object at 0x7d47d407fd00>: Failed to establish a new connection: [Errno 111] Connection refused')': /session/f65011fd29f598ffa407b7a6d133d1c9/se/log
[09:49:02][WARNING] urllib3.connectionpool: Retrying (Retry(total=1, connect=None, read=None, redirect=None, status=None)) after connection broken by 'NewConnectionError('<urllib3.connection.HTTPConnection object at 0x7d47d407fdf0>: Failed to establish a new connection: [Errno 111] Connection refused')': /session/f65011fd29f598ffa407b7a6d133d1c9/se/log
[09:49:02][WARNING] urllib3.connectionpool: Retrying (Retry(total=0, connect=None, read=None, redirect=None, status=None)) after connection broken by 'NewConnectionError('<urllib3.connection.HTTPConnection object at 0x7d47d3f35d80>: Failed to establish a new connection: [Errno 111] Connection refused')': /session/f65011fd29f598ffa407b7a6d133d1c9/se/log
[09:49:02][WARNING] detection-advanced: Failed to capture crash artifacts: HTTPConnectionPool(host='localhost', port=45985): Max retries exceeded with url: /session/f65011fd29f598ffa407b7a6d133d1c9/se/log (Caused by NewConnectionError('<urllib3.connection.HTTPConnection object at 0x7d47d3f34400>: Failed to establish a new connection: [Errno 111] Connection refused'))
[09:49:02][WARNING] urllib3.connectionpool: Retrying (Retry(total=2, connect=None, read=None, redirect=None, status=None)) after connection broken by 'NewConnectionError('<urllib3.connection.HTTPConnection object at 0x7d47d3f342b0>: Failed to establish a new connection: [Errno 111] Connection refused')': /session/f65011fd29f598ffa407b7a6d133d1c9/se/log
[09:49:02][WARNING] urllib3.connectionpool: Retrying (Retry(total=1, connect=None, read=None, redirect=None, status=None)) after connection broken by 'NewConnectionError('<urllib3.connection.HTTPConnection object at 0x7d47d3f340d0>: Failed to establish a new connection: [Errno 111] Connection refused')': /session/f65011fd29f598ffa407b7a6d133d1c9/se/log
[09:49:02][WARNING] urllib3.connectionpool: Retrying (Retry(total=0, connect=None, read=None, redirect=None, status=None)) after connection broken by 'NewConnectionError('<urllib3.connection.HTTPConnection object at 0x7d47d3f34130>: Failed to establish a new connection: [Errno 111] Connection refused')': /session/f65011fd29f598ffa407b7a6d133d1c9/se/log
[09:49:02][WARNING] urllib3.connectionpool: Retrying (Retry(total=2, connect=None, read=None, redirect=None, status=None)) after connection broken by 'NewConnectionError('<urllib3.connection.HTTPConnection object at 0x7d47d3f345e0>: Failed to establish a new connection: [Errno 111] Connection refused')': /session/f65011fd29f598ffa407b7a6d133d1c9/se/log
[09:49:02][WARNING] urllib3.connectionpool: Retrying (Retry(total=1, connect=None, read=None, redirect=None, status=None)) after connection broken by 'NewConnectionError('<urllib3.connection.HTTPConnection object at 0x7d47d3f34730>: Failed to establish a new connection: [Errno 111] Connection refused')': /session/f65011fd29f598ffa407b7a6d133d1c9/se/log
[09:49:02][WARNING] urllib3.connectionpool: Retrying (Retry(total=0, connect=None, read=None, redirect=None, status=None)) after connection broken by 'NewConnectionError('<urllib3.connection.HTTPConnection object at 0x7d47d3f34850>: Failed to establish a new connection: [Errno 111] Connection refused')': /session/f65011fd29f598ffa407b7a6d133d1c9/se/log
[09:49:02][WARNING] urllib3.connectionpool: Retrying (Retry(total=2, connect=None, read=None, redirect=None, status=None)) after connection broken by 'NewConnectionError('<urllib3.connection.HTTPConnection object at 0x7d47d3f34c40>: Failed to establish a new connection: [Errno 111] Connection refused')': /session/f65011fd29f598ffa407b7a6d133d1c9
[09:49:02][WARNING] urllib3.connectionpool: Retrying (Retry(total=1, connect=None, read=None, redirect=None, status=None)) after connection broken by 'NewConnectionError('<urllib3.connection.HTTPConnection object at 0x7d47d3f34d30>: Failed to establish a new connection: [Errno 111] Connection refused')': /session/f65011fd29f598ffa407b7a6d133d1c9
[09:49:02][WARNING] urllib3.connectionpool: Retrying (Retry(total=0, connect=None, read=None, redirect=None, status=None)) after connection broken by 'NewConnectionError('<urllib3.connection.HTTPConnection object at 0x7d47d3f352a0>: Failed to establish a new connection: [Errno 111] Connection refused')': /session/f65011fd29f598ffa407b7a6d133d1c9
[09:49:02][WARNING] detection-advanced:  => anomaly => console_check_error => HTTPConnectionPool(host='localhost', port=45985): Max retries exceeded with url: /session/f65011fd29f598ffa407b7a6d133d1c9/se/log (Caused by NewConnectionError('<urllib3.connection.HTTPConnection object at 0x7d47d3f34430>: Failed to establish a new connection: [Errno 111] Connection refused'))
[09:49:02][WARNING] detection-advanced:  => anomaly => security_check_error => HTTPConnectionPool(host='localhost', port=45985): Max retries exceeded with url: /session/f65011fd29f598ffa407b7a6d133d1c9/se/log (Caused by NewConnectionError('<urllib3.connection.HTTPConnection object at 0x7d47d3f34a00>: Failed to establish a new connection: [Errno 111] Connection refused'))
[09:49:02][INFO] detection-advanced: Finished => mutated_0002.html, took 679.88s
[09:49:02][DEBUG] detection-advanced: [write_coverage_summary] self.coverage_map keys: dict_keys([])
[09:49:02][INFO] detection-advanced: [COVERAGE] coverage_summary => /home/dhia/browser-fuzzer/Dissertation/logger/run_20250327_080734/round_002/crash_results/coverage_summary.json
[09:49:02][INFO] detection-advanced: [REPORT] Text report generated: /home/dhia/browser-fuzzer/Dissertation/logger/run_20250327_080734/round_002/crash_results/reports/full_report.txt
[09:49:03][INFO] detection-advanced: [REPORT] JSON report generated: /home/dhia/browser-fuzzer/Dissertation/logger/run_20250327_080734/round_002/crash_results/reports/detailed_report.json

+-----------------+---------+
| Metric          |   Value |
|-----------------+---------|
| Total Tests     |       2 |
| Passed          |       0 |
| Failed          |       2 |
| Critical Issues |       0 |
| High Severity   |       0 |
| Medium Severity |       0 |
| Low Severity    |       0 |
| Info            |       2 |
+-----------------+---------+
[09:49:03][INFO] detection-advanced: Cleaning up temporary files
[09:49:03][INFO] detection-advanced: System cleanup completed
