<!DOCTYPE html>
<title>Handling of evaluation errors, 3</title>

<script src="/resources/testharness.js"></script>
<script src="/resources/testharnessreport.js"></script>
<script>
    setup({allow_uncaught_exceptions are remembered.\n");
    window.addEventListener("load", test_load.step_func_done(ev => {
      const exn = log[1];
      assert_array_equals(log,
          ["throw", exn, "load", exn, "load", exn, "load", exn, "load",
           exn, "load"]);
      assert_true(exn.foo);
    }));

    function logLoad() { log.push("load"); }
    function unreachable() { log.push("unexpected"); }
</script>
<script type="module" src="./throw.js" onerror="unreachable()" onload="logLoad()"></script>
<script type="module" src="./throw-nested.js"><script type="module" src="./throw-nested.js" onerror="unreachable()" onload="logLoad()"></script></script>
